2020-11-17T12:24:03.2103360+05:30  [FTL] Application startup exception (6c57a5ba)
System.ArgumentException: The directory name E:\Git Projects\DotNetCoreCrudOperation\ is invalid.
Parameter name: path
   at System.IO.FileSystemWatcher..ctor(String path, String filter)
   at System.IO.FileSystemWatcher..ctor(String path)
   at Microsoft.Extensions.FileProviders.PhysicalFileProvider.CreateFileWatcher(String root)
   at Microsoft.Extensions.FileProviders.PhysicalFileProvider..ctor(String root)
   at PickfordsIntranet.WebAdmin.Startup.Configure(IApplicationBuilder app, IHostingEnvironment env, ILoggerFactory loggerFactory, IMessage emailMessage) in D:\Projects\Git Projects\DotNet\DotNetCore\DotNetCoreCrudOperation\DotNetCoreCrudOperation\DotNetCoreCrudOperation.WebAdmin\Startup.cs:line 172
--- End of stack trace from previous location where exception was thrown ---
   at System.Runtime.ExceptionServices.ExceptionDispatchInfo.Throw()
   at Microsoft.AspNetCore.Hosting.ConventionBasedStartup.Configure(IApplicationBuilder app)
   at Microsoft.AspNetCore.ApplicationInsights.HostingStartup.ApplicationInsightsLoggerStartupFilter.<>c__DisplayClass0_0.<Configure>b__0(IApplicationBuilder builder)
   at Microsoft.ApplicationInsights.AspNetCore.ApplicationInsightsStartupFilter.<>c__DisplayClass0_0.<Configure>b__0(IApplicationBuilder app)
   at Microsoft.AspNetCore.Hosting.Internal.AutoRequestServicesStartupFilter.<>c__DisplayClass0_0.<Configure>b__0(IApplicationBuilder builder)
   at Microsoft.AspNetCore.Hosting.Internal.WebHost.BuildApplication()
2020-11-17T12:25:38.6266787+05:30  [FTL] Application startup exception (6c57a5ba)
System.ArgumentException: The directory name E:\Git Projects\DotNetCore\DotNetCoreCrudOperation\ is invalid.
Parameter name: path
   at System.IO.FileSystemWatcher..ctor(String path, String filter)
   at System.IO.FileSystemWatcher..ctor(String path)
   at Microsoft.Extensions.FileProviders.PhysicalFileProvider.CreateFileWatcher(String root)
   at Microsoft.Extensions.FileProviders.PhysicalFileProvider..ctor(String root)
   at PickfordsIntranet.WebAdmin.Startup.Configure(IApplicationBuilder app, IHostingEnvironment env, ILoggerFactory loggerFactory, IMessage emailMessage) in D:\Projects\Git Projects\DotNet\DotNetCore\DotNetCoreCrudOperation\DotNetCoreCrudOperation\DotNetCoreCrudOperation.WebAdmin\Startup.cs:line 172
--- End of stack trace from previous location where exception was thrown ---
   at System.Runtime.ExceptionServices.ExceptionDispatchInfo.Throw()
   at Microsoft.AspNetCore.Hosting.ConventionBasedStartup.Configure(IApplicationBuilder app)
   at Microsoft.AspNetCore.ApplicationInsights.HostingStartup.ApplicationInsightsLoggerStartupFilter.<>c__DisplayClass0_0.<Configure>b__0(IApplicationBuilder builder)
   at Microsoft.ApplicationInsights.AspNetCore.ApplicationInsightsStartupFilter.<>c__DisplayClass0_0.<Configure>b__0(IApplicationBuilder app)
   at Microsoft.AspNetCore.Hosting.Internal.AutoRequestServicesStartupFilter.<>c__DisplayClass0_0.<Configure>b__0(IApplicationBuilder builder)
   at Microsoft.AspNetCore.Hosting.Internal.WebHost.BuildApplication()
2020-11-17T12:26:54.4549855+05:30 0HM4AONB3RKV4:00000006 [ERR] A network-related or instance-specific error occurred while establishing a connection to SQL Server. The server was not found or was not accessible. Verify that the instance name is correct and that SQL Server is configured to allow remote connections. (provider: Named Pipes Provider, error: 40 - Could not open a connection to SQL Server) (5ee8393c)
System.Data.SqlClient.SqlException (0x80131904): A network-related or instance-specific error occurred while establishing a connection to SQL Server. The server was not found or was not accessible. Verify that the instance name is correct and that SQL Server is configured to allow remote connections. (provider: Named Pipes Provider, error: 40 - Could not open a connection to SQL Server) ---> System.ComponentModel.Win32Exception (0x80004005): The network path was not found
   at PickfordsIntranet.Services.AuthService.UserAuthenticate(AuthUserVM user) in D:\Projects\Git Projects\DotNet\DotNetCore\DotNetCoreCrudOperation\DotNetCoreCrudOperation\DotNetCoreCrudOperation.Services\AuthService.cs:line 51
   at PickfordsIntranet.WebAdmin.Controllers.AccountController.Login(AuthUserVM user) in D:\Projects\Git Projects\DotNet\DotNetCore\DotNetCoreCrudOperation\DotNetCoreCrudOperation\DotNetCoreCrudOperation.WebAdmin\Controllers\AccountController.cs:line 70
ClientConnectionId:00000000-0000-0000-0000-000000000000
Error Number:53,State:0,Class:20
2020-11-17T12:26:54.4699467+05:30 0HM4AONB3RKV4:00000006 [ERR] The view '"/Error"' was not found. Searched locations: ["/Error"] (9bb2756c)
2020-11-17T12:26:54.6127284+05:30 0HM4AONB3RKV4:00000006 [ERR] An unhandled exception has occurred while executing the request (cf926119)
System.InvalidOperationException: The view '/Error' was not found. The following locations were searched:
/Error
   at Microsoft.AspNetCore.Mvc.ViewEngines.ViewEngineResult.EnsureSuccessful(IEnumerable`1 originalLocations)
   at Microsoft.AspNetCore.Mvc.ViewResult.<ExecuteResultAsync>d__26.MoveNext()
--- End of stack trace from previous location where exception was thrown ---
   at System.Runtime.ExceptionServices.ExceptionDispatchInfo.Throw()
   at System.Runtime.CompilerServices.TaskAwaiter.HandleNonSuccessAndDebuggerNotification(Task task)
   at Microsoft.AspNetCore.Mvc.Internal.ResourceInvoker.<InvokeResultAsync>d__19.MoveNext()
--- End of stack trace from previous location where exception was thrown ---
   at System.Runtime.ExceptionServices.ExceptionDispatchInfo.Throw()
   at System.Runtime.CompilerServices.TaskAwaiter.HandleNonSuccessAndDebuggerNotification(Task task)
   at Microsoft.AspNetCore.Mvc.Internal.ResourceInvoker.<InvokeNextResultFilterAsync>d__24.MoveNext()
--- End of stack trace from previous location where exception was thrown ---
   at System.Runtime.ExceptionServices.ExceptionDispatchInfo.Throw()
   at Microsoft.AspNetCore.Mvc.Internal.ResourceInvoker.Rethrow(ResultExecutedContext context)
   at Microsoft.AspNetCore.Mvc.Internal.ResourceInvoker.Next(State& next, Scope& scope, Object& state, Boolean& isCompleted)
   at Microsoft.AspNetCore.Mvc.Internal.ResourceInvoker.<InvokeNextResourceFilter>d__22.MoveNext()
--- End of stack trace from previous location where exception was thrown ---
   at System.Runtime.ExceptionServices.ExceptionDispatchInfo.Throw()
   at Microsoft.AspNetCore.Mvc.Internal.ResourceInvoker.Rethrow(ResourceExecutedContext context)
   at Microsoft.AspNetCore.Mvc.Internal.ResourceInvoker.Next(State& next, Scope& scope, Object& state, Boolean& isCompleted)
   at Microsoft.AspNetCore.Mvc.Internal.ResourceInvoker.<InvokeFilterPipelineAsync>d__17.MoveNext()
--- End of stack trace from previous location where exception was thrown ---
   at System.Runtime.ExceptionServices.ExceptionDispatchInfo.Throw()
   at System.Runtime.CompilerServices.TaskAwaiter.HandleNonSuccessAndDebuggerNotification(Task task)
   at Microsoft.AspNetCore.Mvc.Internal.ResourceInvoker.<InvokeAsync>d__15.MoveNext()
--- End of stack trace from previous location where exception was thrown ---
   at System.Runtime.ExceptionServices.ExceptionDispatchInfo.Throw()
   at System.Runtime.CompilerServices.TaskAwaiter.HandleNonSuccessAndDebuggerNotification(Task task)
   at Microsoft.AspNetCore.Builder.RouterMiddleware.<Invoke>d__4.MoveNext()
--- End of stack trace from previous location where exception was thrown ---
   at System.Runtime.ExceptionServices.ExceptionDispatchInfo.Throw()
   at System.Runtime.CompilerServices.TaskAwaiter.HandleNonSuccessAndDebuggerNotification(Task task)
   at Microsoft.AspNetCore.Authentication.AuthenticationMiddleware.<Invoke>d__6.MoveNext()
--- End of stack trace from previous location where exception was thrown ---
   at System.Runtime.ExceptionServices.ExceptionDispatchInfo.Throw()
   at System.Runtime.CompilerServices.TaskAwaiter.HandleNonSuccessAndDebuggerNotification(Task task)
   at Microsoft.AspNetCore.Diagnostics.EntityFrameworkCore.MigrationsEndPointMiddleware.<Invoke>d__4.MoveNext()
--- End of stack trace from previous location where exception was thrown ---
   at System.Runtime.ExceptionServices.ExceptionDispatchInfo.Throw()
   at System.Runtime.CompilerServices.TaskAwaiter.HandleNonSuccessAndDebuggerNotification(Task task)
   at Microsoft.AspNetCore.Diagnostics.EntityFrameworkCore.DatabaseErrorPageMiddleware.<Invoke>d__6.MoveNext()
--- End of stack trace from previous location where exception was thrown ---
   at System.Runtime.ExceptionServices.ExceptionDispatchInfo.Throw()
   at Microsoft.AspNetCore.Diagnostics.EntityFrameworkCore.DatabaseErrorPageMiddleware.<Invoke>d__6.MoveNext()
--- End of stack trace from previous location where exception was thrown ---
   at System.Runtime.ExceptionServices.ExceptionDispatchInfo.Throw()
   at System.Runtime.CompilerServices.TaskAwaiter.HandleNonSuccessAndDebuggerNotification(Task task)
   at Microsoft.AspNetCore.Diagnostics.DeveloperExceptionPageMiddleware.<Invoke>d__7.MoveNext()
